2024-10-29 01:35:38,082 - __main__ - ERROR - [app.py:371] - Input processing error: You have to specify either text or audios. Both cannot be none.
2024-10-29 01:35:59,813 - __main__ - ERROR - [app.py:371] - Input processing error: You have to specify either text or audios. Both cannot be none.
2024-10-29 01:44:17,237 - __main__ - ERROR - [app.py:412] - Translation error: The following `model_kwargs` are not used by the model: ['src_lang'] (note: typos in the generate arguments will also show up in this list)
2024-10-30 23:28:06,776 - __main__ - ERROR - [app.py:412] - Translation error: The following `model_kwargs` are not used by the model: ['src_lang'] (note: typos in the generate arguments will also show up in this list)
2024-10-30 23:59:47,846 - __main__ - ERROR - [app.py:412] - Translation error: The following `model_kwargs` are not used by the model: ['task'] (note: typos in the generate arguments will also show up in this list)
2024-10-31 00:08:20,748 - __main__ - ERROR - [app.py:413] - Translation error: `input_ids`,`input_features` and `inputs_embeds` are all empty. Make sure at least one of them is not.
2024-10-31 00:41:37,100 - __main__ - ERROR - [app.py:397] - Input processing error: name 'audio_numpy' is not defined
2024-10-31 00:52:00,270 - __main__ - ERROR - [app.py:401] - Input processing error: name 'processor' is not defined
2024-10-31 20:45:38,816 - __main__ - ERROR - [app.py:401] - Input processing error: name 'processor' is not defined
2024-10-31 21:09:11,045 - __main__ - ERROR - [app.py:402] - Input processing error: You have to specify either text or audios. Both cannot be none.
2024-10-31 21:47:39,443 - __main__ - ERROR - [app.py:426] - Output processing error: 'tuple' object has no attribute 'waveform'
2024-11-02 20:19:26,988 - __main__ - ERROR - [app.py:426] - Output processing error: 'tuple' object has no attribute 'waveform'
2024-11-02 22:05:04,132 - __main__ - ERROR - [app.py:180] - Error initializing model: facebook/seamless-m4t-medium does not appear to have a file named preprocessor_config.json. Checkout 'https://huggingface.co/facebook/seamless-m4t-medium/tree/main' for available files.
Traceback (most recent call last):
  File "/Users/robmills/audio-translation/.venv/lib/python3.12/site-packages/huggingface_hub/utils/_http.py", line 406, in hf_raise_for_status
    response.raise_for_status()
  File "/Users/robmills/audio-translation/.venv/lib/python3.12/site-packages/requests/models.py", line 1024, in raise_for_status
    raise HTTPError(http_error_msg, response=self)
requests.exceptions.HTTPError: 404 Client Error: Not Found for url: https://huggingface.co/facebook/seamless-m4t-medium/resolve/main/preprocessor_config.json

The above exception was the direct cause of the following exception:

Traceback (most recent call last):
  File "/Users/robmills/audio-translation/.venv/lib/python3.12/site-packages/transformers/utils/hub.py", line 403, in cached_file
    resolved_file = hf_hub_download(
                    ^^^^^^^^^^^^^^^^
  File "/Users/robmills/audio-translation/.venv/lib/python3.12/site-packages/huggingface_hub/utils/_validators.py", line 114, in _inner_fn
    return fn(*args, **kwargs)
           ^^^^^^^^^^^^^^^^^^^
  File "/Users/robmills/audio-translation/.venv/lib/python3.12/site-packages/huggingface_hub/file_download.py", line 862, in hf_hub_download
    return _hf_hub_download_to_cache_dir(
           ^^^^^^^^^^^^^^^^^^^^^^^^^^^^^^
  File "/Users/robmills/audio-translation/.venv/lib/python3.12/site-packages/huggingface_hub/file_download.py", line 925, in _hf_hub_download_to_cache_dir
    (url_to_download, etag, commit_hash, expected_size, head_call_error) = _get_metadata_or_catch_error(
                                                                           ^^^^^^^^^^^^^^^^^^^^^^^^^^^^^
  File "/Users/robmills/audio-translation/.venv/lib/python3.12/site-packages/huggingface_hub/file_download.py", line 1376, in _get_metadata_or_catch_error
    metadata = get_hf_file_metadata(
               ^^^^^^^^^^^^^^^^^^^^^
  File "/Users/robmills/audio-translation/.venv/lib/python3.12/site-packages/huggingface_hub/utils/_validators.py", line 114, in _inner_fn
    return fn(*args, **kwargs)
           ^^^^^^^^^^^^^^^^^^^
  File "/Users/robmills/audio-translation/.venv/lib/python3.12/site-packages/huggingface_hub/file_download.py", line 1296, in get_hf_file_metadata
    r = _request_wrapper(
        ^^^^^^^^^^^^^^^^^
  File "/Users/robmills/audio-translation/.venv/lib/python3.12/site-packages/huggingface_hub/file_download.py", line 277, in _request_wrapper
    response = _request_wrapper(
               ^^^^^^^^^^^^^^^^^
  File "/Users/robmills/audio-translation/.venv/lib/python3.12/site-packages/huggingface_hub/file_download.py", line 301, in _request_wrapper
    hf_raise_for_status(response)
  File "/Users/robmills/audio-translation/.venv/lib/python3.12/site-packages/huggingface_hub/utils/_http.py", line 417, in hf_raise_for_status
    raise _format(EntryNotFoundError, message, response) from e
huggingface_hub.errors.EntryNotFoundError: 404 Client Error. (Request ID: Root=1-6726a210-7d000b0436bcc7d712bb1501;de1b4673-91f1-4b82-a310-2bb423d6715e)

Entry Not Found for url: https://huggingface.co/facebook/seamless-m4t-medium/resolve/main/preprocessor_config.json.

The above exception was the direct cause of the following exception:

Traceback (most recent call last):
  File "/Users/robmills/audio-translation/Backend/app.py", line 166, in _load_model
    self.processor = SeamlessM4TProcessor.from_pretrained(MODEL_NAME, token=auth_token)
                     ^^^^^^^^^^^^^^^^^^^^^^^^^^^^^^^^^^^^^^^^^^^^^^^^^^^^^^^^^^^^^^^^^^
  File "/Users/robmills/audio-translation/.venv/lib/python3.12/site-packages/transformers/processing_utils.py", line 944, in from_pretrained
    args = cls._get_arguments_from_pretrained(pretrained_model_name_or_path, **kwargs)
           ^^^^^^^^^^^^^^^^^^^^^^^^^^^^^^^^^^^^^^^^^^^^^^^^^^^^^^^^^^^^^^^^^^^^^^^^^^^
  File "/Users/robmills/audio-translation/.venv/lib/python3.12/site-packages/transformers/processing_utils.py", line 990, in _get_arguments_from_pretrained
    args.append(attribute_class.from_pretrained(pretrained_model_name_or_path, **kwargs))
                ^^^^^^^^^^^^^^^^^^^^^^^^^^^^^^^^^^^^^^^^^^^^^^^^^^^^^^^^^^^^^^^^^^^^^^^^
  File "/Users/robmills/audio-translation/.venv/lib/python3.12/site-packages/transformers/feature_extraction_utils.py", line 383, in from_pretrained
    feature_extractor_dict, kwargs = cls.get_feature_extractor_dict(pretrained_model_name_or_path, **kwargs)
                                     ^^^^^^^^^^^^^^^^^^^^^^^^^^^^^^^^^^^^^^^^^^^^^^^^^^^^^^^^^^^^^^^^^^^^^^^
  File "/Users/robmills/audio-translation/.venv/lib/python3.12/site-packages/transformers/feature_extraction_utils.py", line 509, in get_feature_extractor_dict
    resolved_feature_extractor_file = cached_file(
                                      ^^^^^^^^^^^^
  File "/Users/robmills/audio-translation/.venv/lib/python3.12/site-packages/transformers/utils/hub.py", line 459, in cached_file
    raise EnvironmentError(
OSError: facebook/seamless-m4t-medium does not appear to have a file named preprocessor_config.json. Checkout 'https://huggingface.co/facebook/seamless-m4t-medium/tree/main' for available files.
2024-11-02 22:05:04,139 - __main__ - ERROR - [app.py:568] - Failed to start application: facebook/seamless-m4t-medium does not appear to have a file named preprocessor_config.json. Checkout 'https://huggingface.co/facebook/seamless-m4t-medium/tree/main' for available files.
Traceback (most recent call last):
  File "/Users/robmills/audio-translation/.venv/lib/python3.12/site-packages/huggingface_hub/utils/_http.py", line 406, in hf_raise_for_status
    response.raise_for_status()
  File "/Users/robmills/audio-translation/.venv/lib/python3.12/site-packages/requests/models.py", line 1024, in raise_for_status
    raise HTTPError(http_error_msg, response=self)
requests.exceptions.HTTPError: 404 Client Error: Not Found for url: https://huggingface.co/facebook/seamless-m4t-medium/resolve/main/preprocessor_config.json

The above exception was the direct cause of the following exception:

Traceback (most recent call last):
  File "/Users/robmills/audio-translation/.venv/lib/python3.12/site-packages/transformers/utils/hub.py", line 403, in cached_file
    resolved_file = hf_hub_download(
                    ^^^^^^^^^^^^^^^^
  File "/Users/robmills/audio-translation/.venv/lib/python3.12/site-packages/huggingface_hub/utils/_validators.py", line 114, in _inner_fn
    return fn(*args, **kwargs)
           ^^^^^^^^^^^^^^^^^^^
  File "/Users/robmills/audio-translation/.venv/lib/python3.12/site-packages/huggingface_hub/file_download.py", line 862, in hf_hub_download
    return _hf_hub_download_to_cache_dir(
           ^^^^^^^^^^^^^^^^^^^^^^^^^^^^^^
  File "/Users/robmills/audio-translation/.venv/lib/python3.12/site-packages/huggingface_hub/file_download.py", line 925, in _hf_hub_download_to_cache_dir
    (url_to_download, etag, commit_hash, expected_size, head_call_error) = _get_metadata_or_catch_error(
                                                                           ^^^^^^^^^^^^^^^^^^^^^^^^^^^^^
  File "/Users/robmills/audio-translation/.venv/lib/python3.12/site-packages/huggingface_hub/file_download.py", line 1376, in _get_metadata_or_catch_error
    metadata = get_hf_file_metadata(
               ^^^^^^^^^^^^^^^^^^^^^
  File "/Users/robmills/audio-translation/.venv/lib/python3.12/site-packages/huggingface_hub/utils/_validators.py", line 114, in _inner_fn
    return fn(*args, **kwargs)
           ^^^^^^^^^^^^^^^^^^^
  File "/Users/robmills/audio-translation/.venv/lib/python3.12/site-packages/huggingface_hub/file_download.py", line 1296, in get_hf_file_metadata
    r = _request_wrapper(
        ^^^^^^^^^^^^^^^^^
  File "/Users/robmills/audio-translation/.venv/lib/python3.12/site-packages/huggingface_hub/file_download.py", line 277, in _request_wrapper
    response = _request_wrapper(
               ^^^^^^^^^^^^^^^^^
  File "/Users/robmills/audio-translation/.venv/lib/python3.12/site-packages/huggingface_hub/file_download.py", line 301, in _request_wrapper
    hf_raise_for_status(response)
  File "/Users/robmills/audio-translation/.venv/lib/python3.12/site-packages/huggingface_hub/utils/_http.py", line 417, in hf_raise_for_status
    raise _format(EntryNotFoundError, message, response) from e
huggingface_hub.errors.EntryNotFoundError: 404 Client Error. (Request ID: Root=1-6726a210-7d000b0436bcc7d712bb1501;de1b4673-91f1-4b82-a310-2bb423d6715e)

Entry Not Found for url: https://huggingface.co/facebook/seamless-m4t-medium/resolve/main/preprocessor_config.json.

The above exception was the direct cause of the following exception:

Traceback (most recent call last):
  File "/Users/robmills/audio-translation/Backend/app.py", line 546, in <module>
    if None in ModelManager().get_model_components():
               ^^^^^^^^^^^^^^
  File "/Users/robmills/audio-translation/Backend/app.py", line 146, in __new__
    cls._instance._initialize()
  File "/Users/robmills/audio-translation/Backend/app.py", line 155, in _initialize
    self._load_model()
  File "/Users/robmills/audio-translation/Backend/app.py", line 166, in _load_model
    self.processor = SeamlessM4TProcessor.from_pretrained(MODEL_NAME, token=auth_token)
                     ^^^^^^^^^^^^^^^^^^^^^^^^^^^^^^^^^^^^^^^^^^^^^^^^^^^^^^^^^^^^^^^^^^
  File "/Users/robmills/audio-translation/.venv/lib/python3.12/site-packages/transformers/processing_utils.py", line 944, in from_pretrained
    args = cls._get_arguments_from_pretrained(pretrained_model_name_or_path, **kwargs)
           ^^^^^^^^^^^^^^^^^^^^^^^^^^^^^^^^^^^^^^^^^^^^^^^^^^^^^^^^^^^^^^^^^^^^^^^^^^^
  File "/Users/robmills/audio-translation/.venv/lib/python3.12/site-packages/transformers/processing_utils.py", line 990, in _get_arguments_from_pretrained
    args.append(attribute_class.from_pretrained(pretrained_model_name_or_path, **kwargs))
                ^^^^^^^^^^^^^^^^^^^^^^^^^^^^^^^^^^^^^^^^^^^^^^^^^^^^^^^^^^^^^^^^^^^^^^^^
  File "/Users/robmills/audio-translation/.venv/lib/python3.12/site-packages/transformers/feature_extraction_utils.py", line 383, in from_pretrained
    feature_extractor_dict, kwargs = cls.get_feature_extractor_dict(pretrained_model_name_or_path, **kwargs)
                                     ^^^^^^^^^^^^^^^^^^^^^^^^^^^^^^^^^^^^^^^^^^^^^^^^^^^^^^^^^^^^^^^^^^^^^^^
  File "/Users/robmills/audio-translation/.venv/lib/python3.12/site-packages/transformers/feature_extraction_utils.py", line 509, in get_feature_extractor_dict
    resolved_feature_extractor_file = cached_file(
                                      ^^^^^^^^^^^^
  File "/Users/robmills/audio-translation/.venv/lib/python3.12/site-packages/transformers/utils/hub.py", line 459, in cached_file
    raise EnvironmentError(
OSError: facebook/seamless-m4t-medium does not appear to have a file named preprocessor_config.json. Checkout 'https://huggingface.co/facebook/seamless-m4t-medium/tree/main' for available files.
2024-11-02 22:05:22,520 - __main__ - ERROR - [app.py:180] - Error initializing model: facebook/seamless-m4t-medium does not appear to have a file named preprocessor_config.json. Checkout 'https://huggingface.co/facebook/seamless-m4t-medium/tree/main' for available files.
Traceback (most recent call last):
  File "/Users/robmills/audio-translation/.venv/lib/python3.12/site-packages/huggingface_hub/utils/_http.py", line 406, in hf_raise_for_status
    response.raise_for_status()
  File "/Users/robmills/audio-translation/.venv/lib/python3.12/site-packages/requests/models.py", line 1024, in raise_for_status
    raise HTTPError(http_error_msg, response=self)
requests.exceptions.HTTPError: 404 Client Error: Not Found for url: https://huggingface.co/facebook/seamless-m4t-medium/resolve/main/preprocessor_config.json

The above exception was the direct cause of the following exception:

Traceback (most recent call last):
  File "/Users/robmills/audio-translation/.venv/lib/python3.12/site-packages/transformers/utils/hub.py", line 403, in cached_file
    resolved_file = hf_hub_download(
                    ^^^^^^^^^^^^^^^^
  File "/Users/robmills/audio-translation/.venv/lib/python3.12/site-packages/huggingface_hub/utils/_validators.py", line 114, in _inner_fn
    return fn(*args, **kwargs)
           ^^^^^^^^^^^^^^^^^^^
  File "/Users/robmills/audio-translation/.venv/lib/python3.12/site-packages/huggingface_hub/file_download.py", line 862, in hf_hub_download
    return _hf_hub_download_to_cache_dir(
           ^^^^^^^^^^^^^^^^^^^^^^^^^^^^^^
  File "/Users/robmills/audio-translation/.venv/lib/python3.12/site-packages/huggingface_hub/file_download.py", line 925, in _hf_hub_download_to_cache_dir
    (url_to_download, etag, commit_hash, expected_size, head_call_error) = _get_metadata_or_catch_error(
                                                                           ^^^^^^^^^^^^^^^^^^^^^^^^^^^^^
  File "/Users/robmills/audio-translation/.venv/lib/python3.12/site-packages/huggingface_hub/file_download.py", line 1376, in _get_metadata_or_catch_error
    metadata = get_hf_file_metadata(
               ^^^^^^^^^^^^^^^^^^^^^
  File "/Users/robmills/audio-translation/.venv/lib/python3.12/site-packages/huggingface_hub/utils/_validators.py", line 114, in _inner_fn
    return fn(*args, **kwargs)
           ^^^^^^^^^^^^^^^^^^^
  File "/Users/robmills/audio-translation/.venv/lib/python3.12/site-packages/huggingface_hub/file_download.py", line 1296, in get_hf_file_metadata
    r = _request_wrapper(
        ^^^^^^^^^^^^^^^^^
  File "/Users/robmills/audio-translation/.venv/lib/python3.12/site-packages/huggingface_hub/file_download.py", line 277, in _request_wrapper
    response = _request_wrapper(
               ^^^^^^^^^^^^^^^^^
  File "/Users/robmills/audio-translation/.venv/lib/python3.12/site-packages/huggingface_hub/file_download.py", line 301, in _request_wrapper
    hf_raise_for_status(response)
  File "/Users/robmills/audio-translation/.venv/lib/python3.12/site-packages/huggingface_hub/utils/_http.py", line 417, in hf_raise_for_status
    raise _format(EntryNotFoundError, message, response) from e
huggingface_hub.errors.EntryNotFoundError: 404 Client Error. (Request ID: Root=1-6726a222-6387461414fd3c042eb1a605;f46e9a1b-c939-4011-970a-a97d11cc6f30)

Entry Not Found for url: https://huggingface.co/facebook/seamless-m4t-medium/resolve/main/preprocessor_config.json.

The above exception was the direct cause of the following exception:

Traceback (most recent call last):
  File "/Users/robmills/audio-translation/Backend/app.py", line 166, in _load_model
    self.processor = SeamlessM4TProcessor.from_pretrained(MODEL_NAME, token=auth_token)
                     ^^^^^^^^^^^^^^^^^^^^^^^^^^^^^^^^^^^^^^^^^^^^^^^^^^^^^^^^^^^^^^^^^^
  File "/Users/robmills/audio-translation/.venv/lib/python3.12/site-packages/transformers/processing_utils.py", line 944, in from_pretrained
    args = cls._get_arguments_from_pretrained(pretrained_model_name_or_path, **kwargs)
           ^^^^^^^^^^^^^^^^^^^^^^^^^^^^^^^^^^^^^^^^^^^^^^^^^^^^^^^^^^^^^^^^^^^^^^^^^^^
  File "/Users/robmills/audio-translation/.venv/lib/python3.12/site-packages/transformers/processing_utils.py", line 990, in _get_arguments_from_pretrained
    args.append(attribute_class.from_pretrained(pretrained_model_name_or_path, **kwargs))
                ^^^^^^^^^^^^^^^^^^^^^^^^^^^^^^^^^^^^^^^^^^^^^^^^^^^^^^^^^^^^^^^^^^^^^^^^
  File "/Users/robmills/audio-translation/.venv/lib/python3.12/site-packages/transformers/feature_extraction_utils.py", line 383, in from_pretrained
    feature_extractor_dict, kwargs = cls.get_feature_extractor_dict(pretrained_model_name_or_path, **kwargs)
                                     ^^^^^^^^^^^^^^^^^^^^^^^^^^^^^^^^^^^^^^^^^^^^^^^^^^^^^^^^^^^^^^^^^^^^^^^
  File "/Users/robmills/audio-translation/.venv/lib/python3.12/site-packages/transformers/feature_extraction_utils.py", line 509, in get_feature_extractor_dict
    resolved_feature_extractor_file = cached_file(
                                      ^^^^^^^^^^^^
  File "/Users/robmills/audio-translation/.venv/lib/python3.12/site-packages/transformers/utils/hub.py", line 459, in cached_file
    raise EnvironmentError(
OSError: facebook/seamless-m4t-medium does not appear to have a file named preprocessor_config.json. Checkout 'https://huggingface.co/facebook/seamless-m4t-medium/tree/main' for available files.
2024-11-02 22:05:22,522 - __main__ - ERROR - [app.py:568] - Failed to start application: facebook/seamless-m4t-medium does not appear to have a file named preprocessor_config.json. Checkout 'https://huggingface.co/facebook/seamless-m4t-medium/tree/main' for available files.
Traceback (most recent call last):
  File "/Users/robmills/audio-translation/.venv/lib/python3.12/site-packages/huggingface_hub/utils/_http.py", line 406, in hf_raise_for_status
    response.raise_for_status()
  File "/Users/robmills/audio-translation/.venv/lib/python3.12/site-packages/requests/models.py", line 1024, in raise_for_status
    raise HTTPError(http_error_msg, response=self)
requests.exceptions.HTTPError: 404 Client Error: Not Found for url: https://huggingface.co/facebook/seamless-m4t-medium/resolve/main/preprocessor_config.json

The above exception was the direct cause of the following exception:

Traceback (most recent call last):
  File "/Users/robmills/audio-translation/.venv/lib/python3.12/site-packages/transformers/utils/hub.py", line 403, in cached_file
    resolved_file = hf_hub_download(
                    ^^^^^^^^^^^^^^^^
  File "/Users/robmills/audio-translation/.venv/lib/python3.12/site-packages/huggingface_hub/utils/_validators.py", line 114, in _inner_fn
    return fn(*args, **kwargs)
           ^^^^^^^^^^^^^^^^^^^
  File "/Users/robmills/audio-translation/.venv/lib/python3.12/site-packages/huggingface_hub/file_download.py", line 862, in hf_hub_download
    return _hf_hub_download_to_cache_dir(
           ^^^^^^^^^^^^^^^^^^^^^^^^^^^^^^
  File "/Users/robmills/audio-translation/.venv/lib/python3.12/site-packages/huggingface_hub/file_download.py", line 925, in _hf_hub_download_to_cache_dir
    (url_to_download, etag, commit_hash, expected_size, head_call_error) = _get_metadata_or_catch_error(
                                                                           ^^^^^^^^^^^^^^^^^^^^^^^^^^^^^
  File "/Users/robmills/audio-translation/.venv/lib/python3.12/site-packages/huggingface_hub/file_download.py", line 1376, in _get_metadata_or_catch_error
    metadata = get_hf_file_metadata(
               ^^^^^^^^^^^^^^^^^^^^^
  File "/Users/robmills/audio-translation/.venv/lib/python3.12/site-packages/huggingface_hub/utils/_validators.py", line 114, in _inner_fn
    return fn(*args, **kwargs)
           ^^^^^^^^^^^^^^^^^^^
  File "/Users/robmills/audio-translation/.venv/lib/python3.12/site-packages/huggingface_hub/file_download.py", line 1296, in get_hf_file_metadata
    r = _request_wrapper(
        ^^^^^^^^^^^^^^^^^
  File "/Users/robmills/audio-translation/.venv/lib/python3.12/site-packages/huggingface_hub/file_download.py", line 277, in _request_wrapper
    response = _request_wrapper(
               ^^^^^^^^^^^^^^^^^
  File "/Users/robmills/audio-translation/.venv/lib/python3.12/site-packages/huggingface_hub/file_download.py", line 301, in _request_wrapper
    hf_raise_for_status(response)
  File "/Users/robmills/audio-translation/.venv/lib/python3.12/site-packages/huggingface_hub/utils/_http.py", line 417, in hf_raise_for_status
    raise _format(EntryNotFoundError, message, response) from e
huggingface_hub.errors.EntryNotFoundError: 404 Client Error. (Request ID: Root=1-6726a222-6387461414fd3c042eb1a605;f46e9a1b-c939-4011-970a-a97d11cc6f30)

Entry Not Found for url: https://huggingface.co/facebook/seamless-m4t-medium/resolve/main/preprocessor_config.json.

The above exception was the direct cause of the following exception:

Traceback (most recent call last):
  File "/Users/robmills/audio-translation/Backend/app.py", line 546, in <module>
    if None in ModelManager().get_model_components():
               ^^^^^^^^^^^^^^
  File "/Users/robmills/audio-translation/Backend/app.py", line 146, in __new__
    cls._instance._initialize()
  File "/Users/robmills/audio-translation/Backend/app.py", line 155, in _initialize
    self._load_model()
  File "/Users/robmills/audio-translation/Backend/app.py", line 166, in _load_model
    self.processor = SeamlessM4TProcessor.from_pretrained(MODEL_NAME, token=auth_token)
                     ^^^^^^^^^^^^^^^^^^^^^^^^^^^^^^^^^^^^^^^^^^^^^^^^^^^^^^^^^^^^^^^^^^
  File "/Users/robmills/audio-translation/.venv/lib/python3.12/site-packages/transformers/processing_utils.py", line 944, in from_pretrained
    args = cls._get_arguments_from_pretrained(pretrained_model_name_or_path, **kwargs)
           ^^^^^^^^^^^^^^^^^^^^^^^^^^^^^^^^^^^^^^^^^^^^^^^^^^^^^^^^^^^^^^^^^^^^^^^^^^^
  File "/Users/robmills/audio-translation/.venv/lib/python3.12/site-packages/transformers/processing_utils.py", line 990, in _get_arguments_from_pretrained
    args.append(attribute_class.from_pretrained(pretrained_model_name_or_path, **kwargs))
                ^^^^^^^^^^^^^^^^^^^^^^^^^^^^^^^^^^^^^^^^^^^^^^^^^^^^^^^^^^^^^^^^^^^^^^^^
  File "/Users/robmills/audio-translation/.venv/lib/python3.12/site-packages/transformers/feature_extraction_utils.py", line 383, in from_pretrained
    feature_extractor_dict, kwargs = cls.get_feature_extractor_dict(pretrained_model_name_or_path, **kwargs)
                                     ^^^^^^^^^^^^^^^^^^^^^^^^^^^^^^^^^^^^^^^^^^^^^^^^^^^^^^^^^^^^^^^^^^^^^^^
  File "/Users/robmills/audio-translation/.venv/lib/python3.12/site-packages/transformers/feature_extraction_utils.py", line 509, in get_feature_extractor_dict
    resolved_feature_extractor_file = cached_file(
                                      ^^^^^^^^^^^^
  File "/Users/robmills/audio-translation/.venv/lib/python3.12/site-packages/transformers/utils/hub.py", line 459, in cached_file
    raise EnvironmentError(
OSError: facebook/seamless-m4t-medium does not appear to have a file named preprocessor_config.json. Checkout 'https://huggingface.co/facebook/seamless-m4t-medium/tree/main' for available files.
2024-11-02 23:02:41,987 - app - ERROR - [app.py:838] - Exception on /translate [POST]
Traceback (most recent call last):
  File "/Users/robmills/audio-translation/.venv/lib/python3.12/site-packages/flask/app.py", line 1473, in wsgi_app
    response = self.full_dispatch_request()
               ^^^^^^^^^^^^^^^^^^^^^^^^^^^^
  File "/Users/robmills/audio-translation/.venv/lib/python3.12/site-packages/flask/app.py", line 883, in full_dispatch_request
    return self.finalize_request(rv)
           ^^^^^^^^^^^^^^^^^^^^^^^^^
  File "/Users/robmills/audio-translation/.venv/lib/python3.12/site-packages/flask/app.py", line 902, in finalize_request
    response = self.make_response(rv)
               ^^^^^^^^^^^^^^^^^^^^^^
  File "/Users/robmills/audio-translation/.venv/lib/python3.12/site-packages/flask/app.py", line 1174, in make_response
    raise TypeError(
TypeError: The view function for 'translate_audio' did not return a valid response. The function either returned None or ended without a return statement.
2024-11-02 23:41:00,196 - __main__ - ERROR - [app.py:469] - Output processing error: Expected 2D Tensor, got 3D.
